2020-06-24 14:17:19,993 INFO: Mapng startup [in C:\Users\Engr Princely\map\numerology\__init__.py:63]
2020-06-28 14:41:30,058 INFO: Map startup [in C:\Users\Engr Princely\map\numerology\__init__.py:88]
2020-06-28 15:26:52,074 INFO: Map startup [in C:\Users\Engr Princely\map\numerology\__init__.py:88]
2020-06-28 16:04:43,543 INFO: Map startup [in C:\Users\Engr Princely\map\numerology\__init__.py:88]
2020-06-28 16:05:10,543 INFO: Map startup [in C:\Users\Engr Princely\map\numerology\__init__.py:88]
2020-06-28 16:05:37,537 INFO: Map startup [in C:\Users\Engr Princely\map\numerology\__init__.py:88]
2020-06-28 16:14:24,769 ERROR: Exception on /paysuccess [GET] [in c:\users\engr princely\map\venv\lib\site-packages\flask\app.py:1892]
Traceback (most recent call last):
  File "c:\users\engr princely\map\venv\lib\site-packages\flask\app.py", line 2447, in wsgi_app
    response = self.full_dispatch_request()
  File "c:\users\engr princely\map\venv\lib\site-packages\flask\app.py", line 1952, in full_dispatch_request
    rv = self.handle_user_exception(e)
  File "c:\users\engr princely\map\venv\lib\site-packages\flask\app.py", line 1821, in handle_user_exception
    reraise(exc_type, exc_value, tb)
  File "c:\users\engr princely\map\venv\lib\site-packages\flask\_compat.py", line 39, in reraise
    raise value
  File "c:\users\engr princely\map\venv\lib\site-packages\flask\app.py", line 1950, in full_dispatch_request
    rv = self.dispatch_request()
  File "c:\users\engr princely\map\venv\lib\site-packages\flask\app.py", line 1936, in dispatch_request
    return self.view_functions[rule.endpoint](**req.view_args)
  File "C:\Users\Engr Princely\map\numerology\main\__init__.py", line 46, in paysuccess
    url = req.url
NameError: name 'req' is not defined
2020-06-28 16:23:42,976 ERROR: Exception on /paysuccess [GET] [in c:\users\engr princely\map\venv\lib\site-packages\flask\app.py:1892]
Traceback (most recent call last):
  File "c:\users\engr princely\map\venv\lib\site-packages\flask\app.py", line 2447, in wsgi_app
    response = self.full_dispatch_request()
  File "c:\users\engr princely\map\venv\lib\site-packages\flask\app.py", line 1952, in full_dispatch_request
    rv = self.handle_user_exception(e)
  File "c:\users\engr princely\map\venv\lib\site-packages\flask\app.py", line 1821, in handle_user_exception
    reraise(exc_type, exc_value, tb)
  File "c:\users\engr princely\map\venv\lib\site-packages\flask\_compat.py", line 39, in reraise
    raise value
  File "c:\users\engr princely\map\venv\lib\site-packages\flask\app.py", line 1950, in full_dispatch_request
    rv = self.dispatch_request()
  File "c:\users\engr princely\map\venv\lib\site-packages\flask\app.py", line 1936, in dispatch_request
    return self.view_functions[rule.endpoint](**req.view_args)
  File "C:\Users\Engr Princely\map\numerology\main\__init__.py", line 46, in paysuccess
    url = req.url
NameError: name 'req' is not defined
2020-06-28 16:27:19,122 ERROR: Exception on /paysuccess [GET] [in c:\users\engr princely\map\venv\lib\site-packages\flask\app.py:1892]
Traceback (most recent call last):
  File "c:\users\engr princely\map\venv\lib\site-packages\flask\app.py", line 2447, in wsgi_app
    response = self.full_dispatch_request()
  File "c:\users\engr princely\map\venv\lib\site-packages\flask\app.py", line 1952, in full_dispatch_request
    rv = self.handle_user_exception(e)
  File "c:\users\engr princely\map\venv\lib\site-packages\flask\app.py", line 1821, in handle_user_exception
    reraise(exc_type, exc_value, tb)
  File "c:\users\engr princely\map\venv\lib\site-packages\flask\_compat.py", line 39, in reraise
    raise value
  File "c:\users\engr princely\map\venv\lib\site-packages\flask\app.py", line 1950, in full_dispatch_request
    rv = self.dispatch_request()
  File "c:\users\engr princely\map\venv\lib\site-packages\flask\app.py", line 1936, in dispatch_request
    return self.view_functions[rule.endpoint](**req.view_args)
  File "C:\Users\Engr Princely\map\numerology\main\__init__.py", line 46, in paysuccess
    url = request.url
NameError: name 'req' is not defined
2020-06-28 16:27:47,056 ERROR: Exception on /paysuccess [GET] [in c:\users\engr princely\map\venv\lib\site-packages\flask\app.py:1892]
Traceback (most recent call last):
  File "c:\users\engr princely\map\venv\lib\site-packages\flask\app.py", line 2447, in wsgi_app
    response = self.full_dispatch_request()
  File "c:\users\engr princely\map\venv\lib\site-packages\flask\app.py", line 1952, in full_dispatch_request
    rv = self.handle_user_exception(e)
  File "c:\users\engr princely\map\venv\lib\site-packages\flask\app.py", line 1821, in handle_user_exception
    reraise(exc_type, exc_value, tb)
  File "c:\users\engr princely\map\venv\lib\site-packages\flask\_compat.py", line 39, in reraise
    raise value
  File "c:\users\engr princely\map\venv\lib\site-packages\flask\app.py", line 1950, in full_dispatch_request
    rv = self.dispatch_request()
  File "c:\users\engr princely\map\venv\lib\site-packages\flask\app.py", line 1936, in dispatch_request
    return self.view_functions[rule.endpoint](**req.view_args)
  File "C:\Users\Engr Princely\map\numerology\main\__init__.py", line 46, in paysuccess
    url = request.url
NameError: name 'req' is not defined
2020-06-28 16:29:24,722 ERROR: Exception on /paysuccess [GET] [in c:\users\engr princely\map\venv\lib\site-packages\flask\app.py:1892]
Traceback (most recent call last):
  File "c:\users\engr princely\map\venv\lib\site-packages\flask\app.py", line 2447, in wsgi_app
    response = self.full_dispatch_request()
  File "c:\users\engr princely\map\venv\lib\site-packages\flask\app.py", line 1952, in full_dispatch_request
    rv = self.handle_user_exception(e)
  File "c:\users\engr princely\map\venv\lib\site-packages\flask\app.py", line 1821, in handle_user_exception
    reraise(exc_type, exc_value, tb)
  File "c:\users\engr princely\map\venv\lib\site-packages\flask\_compat.py", line 39, in reraise
    raise value
  File "c:\users\engr princely\map\venv\lib\site-packages\flask\app.py", line 1950, in full_dispatch_request
    rv = self.dispatch_request()
  File "c:\users\engr princely\map\venv\lib\site-packages\flask\app.py", line 1936, in dispatch_request
    return self.view_functions[rule.endpoint](**req.view_args)
  File "C:\Users\Engr Princely\map\numerology\main\__init__.py", line 46, in paysuccess
    url = request.url
NameError: name 'req' is not defined
2020-06-28 16:29:35,056 ERROR: Exception on /paysuccess [GET] [in c:\users\engr princely\map\venv\lib\site-packages\flask\app.py:1892]
Traceback (most recent call last):
  File "c:\users\engr princely\map\venv\lib\site-packages\flask\app.py", line 2447, in wsgi_app
    response = self.full_dispatch_request()
  File "c:\users\engr princely\map\venv\lib\site-packages\flask\app.py", line 1952, in full_dispatch_request
    rv = self.handle_user_exception(e)
  File "c:\users\engr princely\map\venv\lib\site-packages\flask\app.py", line 1821, in handle_user_exception
    reraise(exc_type, exc_value, tb)
  File "c:\users\engr princely\map\venv\lib\site-packages\flask\_compat.py", line 39, in reraise
    raise value
  File "c:\users\engr princely\map\venv\lib\site-packages\flask\app.py", line 1950, in full_dispatch_request
    rv = self.dispatch_request()
  File "c:\users\engr princely\map\venv\lib\site-packages\flask\app.py", line 1936, in dispatch_request
    return self.view_functions[rule.endpoint](**req.view_args)
  File "C:\Users\Engr Princely\map\numerology\main\__init__.py", line 46, in paysuccess
    url = request.url
NameError: name 'req' is not defined
2020-06-28 16:30:52,952 INFO: Map startup [in C:\Users\Engr Princely\map\numerology\__init__.py:88]
2020-06-28 16:31:01,556 ERROR: Exception on /paysuccess [GET] [in c:\users\engr princely\map\venv\lib\site-packages\flask\app.py:1892]
Traceback (most recent call last):
  File "c:\users\engr princely\map\venv\lib\site-packages\flask\app.py", line 2447, in wsgi_app
    response = self.full_dispatch_request()
  File "c:\users\engr princely\map\venv\lib\site-packages\flask\app.py", line 1952, in full_dispatch_request
    rv = self.handle_user_exception(e)
  File "c:\users\engr princely\map\venv\lib\site-packages\flask\app.py", line 1821, in handle_user_exception
    reraise(exc_type, exc_value, tb)
  File "c:\users\engr princely\map\venv\lib\site-packages\flask\_compat.py", line 39, in reraise
    raise value
  File "c:\users\engr princely\map\venv\lib\site-packages\flask\app.py", line 1950, in full_dispatch_request
    rv = self.dispatch_request()
  File "c:\users\engr princely\map\venv\lib\site-packages\flask\app.py", line 1936, in dispatch_request
    return self.view_functions[rule.endpoint](**req.view_args)
  File "C:\Users\Engr Princely\map\numerology\main\__init__.py", line 48, in paysuccess
    component = parse_qs(parsed.query)['resp'][0]
KeyError: 'resp'
2020-06-28 16:49:41,760 ERROR: Exception on /paysuccess [GET] [in c:\users\engr princely\map\venv\lib\site-packages\flask\app.py:1892]
Traceback (most recent call last):
  File "c:\users\engr princely\map\venv\lib\site-packages\flask\app.py", line 2447, in wsgi_app
    response = self.full_dispatch_request()
  File "c:\users\engr princely\map\venv\lib\site-packages\flask\app.py", line 1952, in full_dispatch_request
    rv = self.handle_user_exception(e)
  File "c:\users\engr princely\map\venv\lib\site-packages\flask\app.py", line 1821, in handle_user_exception
    reraise(exc_type, exc_value, tb)
  File "c:\users\engr princely\map\venv\lib\site-packages\flask\_compat.py", line 39, in reraise
    raise value
  File "c:\users\engr princely\map\venv\lib\site-packages\flask\app.py", line 1950, in full_dispatch_request
    rv = self.dispatch_request()
  File "c:\users\engr princely\map\venv\lib\site-packages\flask\app.py", line 1936, in dispatch_request
    return self.view_functions[rule.endpoint](**req.view_args)
  File "C:\Users\Engr Princely\map\numerology\main\__init__.py", line 48, in paysuccess
    component = parse_qs(parsed.query)['resp'][0]
KeyError: 'resp'
