2020-06-28 16:51:00,611 ERROR: Exception on /paysuccess [GET] [in c:\users\engr princely\map\venv\lib\site-packages\flask\app.py:1892]
Traceback (most recent call last):
  File "c:\users\engr princely\map\venv\lib\site-packages\flask\app.py", line 2447, in wsgi_app
    response = self.full_dispatch_request()
  File "c:\users\engr princely\map\venv\lib\site-packages\flask\app.py", line 1952, in full_dispatch_request
    rv = self.handle_user_exception(e)
  File "c:\users\engr princely\map\venv\lib\site-packages\flask\app.py", line 1821, in handle_user_exception
    reraise(exc_type, exc_value, tb)
  File "c:\users\engr princely\map\venv\lib\site-packages\flask\_compat.py", line 39, in reraise
    raise value
  File "c:\users\engr princely\map\venv\lib\site-packages\flask\app.py", line 1950, in full_dispatch_request
    rv = self.dispatch_request()
  File "c:\users\engr princely\map\venv\lib\site-packages\flask\app.py", line 1936, in dispatch_request
    return self.view_functions[rule.endpoint](**req.view_args)
  File "C:\Users\Engr Princely\map\numerology\main\__init__.py", line 48, in paysuccess
    component = parse_qs(parsed.query)['resp'][0]
KeyError: 'resp'
2020-06-29 17:09:19,492 INFO: Map startup [in C:\Users\Engr Princely\map\numerology\__init__.py:88]
2020-06-29 18:02:25,013 INFO: Map startup [in C:\Users\Engr Princely\map\numerology\__init__.py:88]
2020-06-29 18:03:28,126 ERROR: Exception on /reading [GET] [in c:\users\engr princely\map\venv\lib\site-packages\flask\app.py:1892]
Traceback (most recent call last):
  File "c:\users\engr princely\map\venv\lib\site-packages\flask\app.py", line 2447, in wsgi_app
    response = self.full_dispatch_request()
  File "c:\users\engr princely\map\venv\lib\site-packages\flask\app.py", line 1952, in full_dispatch_request
    rv = self.handle_user_exception(e)
  File "c:\users\engr princely\map\venv\lib\site-packages\flask\app.py", line 1821, in handle_user_exception
    reraise(exc_type, exc_value, tb)
  File "c:\users\engr princely\map\venv\lib\site-packages\flask\_compat.py", line 39, in reraise
    raise value
  File "c:\users\engr princely\map\venv\lib\site-packages\flask\app.py", line 1950, in full_dispatch_request
    rv = self.dispatch_request()
  File "c:\users\engr princely\map\venv\lib\site-packages\flask\app.py", line 1936, in dispatch_request
    return self.view_functions[rule.endpoint](**req.view_args)
  File "c:\users\engr princely\map\venv\lib\site-packages\flask_login\utils.py", line 272, in decorated_view
    return func(*args, **kwargs)
  File "C:\Users\Engr Princely\map\numerology\main\__init__.py", line 126, in reading
    p33=r[25],p4=r[26],p44=r[27],year_now=r[28],py_num=r[39],karma=r[30],karma1=[31],karma2=r[32],
IndexError: list index out of range
2020-06-29 18:06:08,020 ERROR: Exception on /reading [GET] [in c:\users\engr princely\map\venv\lib\site-packages\flask\app.py:1892]
Traceback (most recent call last):
  File "c:\users\engr princely\map\venv\lib\site-packages\flask\app.py", line 2447, in wsgi_app
    response = self.full_dispatch_request()
  File "c:\users\engr princely\map\venv\lib\site-packages\flask\app.py", line 1952, in full_dispatch_request
    rv = self.handle_user_exception(e)
  File "c:\users\engr princely\map\venv\lib\site-packages\flask\app.py", line 1821, in handle_user_exception
    reraise(exc_type, exc_value, tb)
  File "c:\users\engr princely\map\venv\lib\site-packages\flask\_compat.py", line 39, in reraise
    raise value
  File "c:\users\engr princely\map\venv\lib\site-packages\flask\app.py", line 1950, in full_dispatch_request
    rv = self.dispatch_request()
  File "c:\users\engr princely\map\venv\lib\site-packages\flask\app.py", line 1936, in dispatch_request
    return self.view_functions[rule.endpoint](**req.view_args)
  File "c:\users\engr princely\map\venv\lib\site-packages\flask_login\utils.py", line 272, in decorated_view
    return func(*args, **kwargs)
  File "C:\Users\Engr Princely\map\numerology\main\__init__.py", line 126, in reading
    p33=r[25],p4=r[26],p44=r[27],year_now=r[28],py_num=r[29],karma=r[30],karma1=[31],karma2=r[32],
IndexError: list index out of range
2020-06-29 18:06:36,907 ERROR: Exception on /reading [GET] [in c:\users\engr princely\map\venv\lib\site-packages\flask\app.py:1892]
Traceback (most recent call last):
  File "c:\users\engr princely\map\venv\lib\site-packages\flask\app.py", line 2447, in wsgi_app
    response = self.full_dispatch_request()
  File "c:\users\engr princely\map\venv\lib\site-packages\flask\app.py", line 1952, in full_dispatch_request
    rv = self.handle_user_exception(e)
  File "c:\users\engr princely\map\venv\lib\site-packages\flask\app.py", line 1821, in handle_user_exception
    reraise(exc_type, exc_value, tb)
  File "c:\users\engr princely\map\venv\lib\site-packages\flask\_compat.py", line 39, in reraise
    raise value
  File "c:\users\engr princely\map\venv\lib\site-packages\flask\app.py", line 1950, in full_dispatch_request
    rv = self.dispatch_request()
  File "c:\users\engr princely\map\venv\lib\site-packages\flask\app.py", line 1936, in dispatch_request
    return self.view_functions[rule.endpoint](**req.view_args)
  File "c:\users\engr princely\map\venv\lib\site-packages\flask_login\utils.py", line 272, in decorated_view
    return func(*args, **kwargs)
  File "C:\Users\Engr Princely\map\numerology\main\__init__.py", line 126, in reading
    p33=r[25],p4=r[26],p44=r[27],year_now=r[28],py_num=r[29],karma=r[30],karma1=[31],karma2=r[32],
IndexError: list index out of range
2020-06-29 18:07:38,238 ERROR: Exception on /reading [GET] [in c:\users\engr princely\map\venv\lib\site-packages\flask\app.py:1892]
Traceback (most recent call last):
  File "c:\users\engr princely\map\venv\lib\site-packages\flask\app.py", line 2447, in wsgi_app
    response = self.full_dispatch_request()
  File "c:\users\engr princely\map\venv\lib\site-packages\flask\app.py", line 1952, in full_dispatch_request
    rv = self.handle_user_exception(e)
  File "c:\users\engr princely\map\venv\lib\site-packages\flask\app.py", line 1821, in handle_user_exception
    reraise(exc_type, exc_value, tb)
  File "c:\users\engr princely\map\venv\lib\site-packages\flask\_compat.py", line 39, in reraise
    raise value
  File "c:\users\engr princely\map\venv\lib\site-packages\flask\app.py", line 1950, in full_dispatch_request
    rv = self.dispatch_request()
  File "c:\users\engr princely\map\venv\lib\site-packages\flask\app.py", line 1936, in dispatch_request
    return self.view_functions[rule.endpoint](**req.view_args)
  File "c:\users\engr princely\map\venv\lib\site-packages\flask_login\utils.py", line 272, in decorated_view
    return func(*args, **kwargs)
  File "C:\Users\Engr Princely\map\numerology\main\__init__.py", line 126, in reading
    Mrity=r[16],cha=r[17],btd1=r[18],bd22=r[19],p1=r[20],p11=r[21],p2=r[22],p22=r[23],p3=r[24],
IndexError: list index out of range
2020-06-29 18:17:06,638 INFO: Map startup [in C:\Users\Engr Princely\map\numerology\__init__.py:88]
2020-06-30 14:29:32,751 INFO: Map startup [in C:\Users\Engr Princely\map\numerology\__init__.py:88]
2020-07-02 18:45:47,849 INFO: Map startup [in C:\Users\Engr Princely\map\numerology\__init__.py:88]
2020-07-03 07:59:07,626 INFO: Map startup [in C:\Users\Engr Princely\map\numerology\__init__.py:88]
2020-07-03 07:59:40,152 INFO: Map startup [in C:\Users\Engr Princely\map\numerology\__init__.py:88]
